 * Serving Flask app "test" (lazy loading)
 * Environment: production
   WARNING: This is a development server. Do not use it in a production deployment.
   Use a production WSGI server instead.
 * Debug mode: off
Traceback (most recent call last):
  File "test.py", line 23, in <module>
    app.run(host="0.0.0.0", port=80)
  File "/home/ubuntu/.local/lib/python3.7/site-packages/flask/app.py", line 990, in run
    run_simple(host, port, self, **options)
  File "/home/ubuntu/.local/lib/python3.7/site-packages/werkzeug/serving.py", line 1010, in run_simple
    inner()
  File "/home/ubuntu/.local/lib/python3.7/site-packages/werkzeug/serving.py", line 963, in inner
    fd=fd,
  File "/home/ubuntu/.local/lib/python3.7/site-packages/werkzeug/serving.py", line 806, in make_server
    host, port, app, request_handler, passthrough_errors, ssl_context, fd=fd
  File "/home/ubuntu/.local/lib/python3.7/site-packages/werkzeug/serving.py", line 699, in __init__
    HTTPServer.__init__(self, server_address, handler)
  File "/usr/lib/python3.7/socketserver.py", line 452, in __init__
    self.server_bind()
  File "/usr/lib/python3.7/http/server.py", line 137, in server_bind
    socketserver.TCPServer.server_bind(self)
  File "/usr/lib/python3.7/socketserver.py", line 466, in server_bind
    self.socket.bind(self.server_address)
PermissionError: [Errno 13] Permission denied
Error in sys.excepthook:
Traceback (most recent call last):
  File "/usr/lib/python3/dist-packages/apport_python_hook.py", line 63, in apport_excepthook
    from apport.fileutils import likely_packaged, get_recent_crashes
  File "/usr/lib/python3/dist-packages/apport/__init__.py", line 5, in <module>
    from apport.report import Report
  File "/usr/lib/python3/dist-packages/apport/report.py", line 30, in <module>
    import apport.fileutils
  File "/usr/lib/python3/dist-packages/apport/fileutils.py", line 23, in <module>
    from apport.packaging_impl import impl as packaging
  File "/usr/lib/python3/dist-packages/apport/packaging_impl.py", line 24, in <module>
    import apt
  File "/usr/lib/python3/dist-packages/apt/__init__.py", line 23, in <module>
    import apt_pkg
ModuleNotFoundError: No module named 'apt_pkg'

Original exception was:
Traceback (most recent call last):
  File "test.py", line 23, in <module>
    app.run(host="0.0.0.0", port=80)
  File "/home/ubuntu/.local/lib/python3.7/site-packages/flask/app.py", line 990, in run
    run_simple(host, port, self, **options)
  File "/home/ubuntu/.local/lib/python3.7/site-packages/werkzeug/serving.py", line 1010, in run_simple
    inner()
  File "/home/ubuntu/.local/lib/python3.7/site-packages/werkzeug/serving.py", line 963, in inner
    fd=fd,
  File "/home/ubuntu/.local/lib/python3.7/site-packages/werkzeug/serving.py", line 806, in make_server
    host, port, app, request_handler, passthrough_errors, ssl_context, fd=fd
  File "/home/ubuntu/.local/lib/python3.7/site-packages/werkzeug/serving.py", line 699, in __init__
    HTTPServer.__init__(self, server_address, handler)
  File "/usr/lib/python3.7/socketserver.py", line 452, in __init__
    self.server_bind()
  File "/usr/lib/python3.7/http/server.py", line 137, in server_bind
    socketserver.TCPServer.server_bind(self)
  File "/usr/lib/python3.7/socketserver.py", line 466, in server_bind
    self.socket.bind(self.server_address)
PermissionError: [Errno 13] Permission denied
